Workbook
Name Produtos: Table_1[[#All],[Produtos]]
Name Produtos: Table_1[[#All],[Produtos]]
Name Produtos: Table_1[[#All],[Produtos]]

Sheet Vendas 2024
A1: Mês | B1: Data | C1: Produto | D1: QT | E1: Cliente | F1: Vendedor | G1: Custo Un | H1: Valor gasto | I1: Valor uni venda | J1: Valor da venda | K1: Tipo de venda | L1: Valor CNPJ | M1: Lucro | N1: Forma de pagam | O1: % Lucro | P1: Recebido loja
A2: 1 | B2: 45313 | C2: Cabo Kingo Iphone 1M | D2: 1 | E2: Lázaro | F2: Rafael | G2: 7 | H2: 7 | I2: 15 | J2: 15 | K2: CPF | L2: 0.53333333 | M2: 8 | P2: Transferido
A3: 1 | B3: 45313 | C3: Mini jogo de luz c/c | D3: 1 | E3: Shopee | F3: Leonardo | G3: 37 | H3: 37 | I3: 55.5 | J3: 55.5 | K3: Shopee | L3: 0.33333333 | M3: 18.5 | P3: Transferido
A4: 1 | B4: 45314 | C4: Mini jogo de luz c/c | D4: 1 | E4: Mayra blayner | F4: Leonardo | G4: 37 | H4: 37 | I4: 60 | J4: 60 | K4: CPF | L4: 0.38333333 | M4: 23 | P4: Transferido
A5: 1 | B5: 45315 | C5: Case Iphone Caixa | D5: 1 | E5: Aleatorio | F5: Rafael | G5: 18 | H5: 18 | I5: 30 | J5: 30 | K5: CPF | L5: 0.4 | M5: 12 | P5: Transferido
A6: 1 | B6: 45316 | C6: Case Iphone Caixa | D6: 1 | E6: Aleatorio | F6: Rafael | G6: 18 | H6: 18 | I6: 20 | J6: 20 | K6: CPF | L6: 0.1 | M6: 2 | P6: Transferido
A7: 1 | B7: 45317 | C7: Powebank hmaster 20k | D7: 1 | E7: Aleatorio | F7: Rafael | G7: 80 | H7: 80 | I7: 140 | J7: 140 | K7: CPF | L7: 0.42857143 | M7: 60 | P7: Transferido
A8: 1 | B8: 45318 | C8: Raquete mata mosquito | D8: 1 | E8: Projeçao | F8: Leonardo | G8: 14 | H8: 14 | I8: 30 | J8: 30 | K8: CNPJ | L8: 0.53333333 | M8: 16 | P8: Transferido
A9: 1 | B9: 45318 | C9: Raquete mata mosquito | D9: 1 | E9: Projeçao | F9: Leonardo | G9: 14 | H9: 14 | I9: 30 | J9: 30 | K9: CNPJ | L9: 0.53333333 | M9: 16 | P9: Transferido
A10: 1 | B10: 45318 | C10: Raquete mata mosquito | D10: 1 | E10: Projeçao | F10: Leonardo | G10: 14 | H10: 14 | I10: 30 | J10: 30 | K10: CNPJ | L10: 0.53333333 | M10: 16 | P10: Transferido
A11: 1 | B11: 45318 | C11: Raquete mata mosquito | D11: 1 | E11: Projeçao | F11: Leonardo | G11: 14 | H11: 14 | I11: 30 | J11: 30 | K11: CNPJ | L11: 0.53333333 | M11: 16 | P11: Transferido
A12: 1 | B12: 45318 | C12: Case Iphone Caixa | D12: 1 | E12: Aleatorio | F12: Rafael | G12: 18 | H12: 18 | I12: 20 | J12: 20 | K12: CPF | L12: 0.1 | M12: 2 | P12: Transferido
A13: 1 | B13: 45318 | C13: Luminária astronauta | D13: 1 | E13: Aleatorio | F13: Rafael | G13: 75 | H13: 75 | I13: 150 | J13: 150 | K13: CPF | L13: 0.5 | M13: 75 | P13: Transferido
... A40: 1 | B40: 45322 | C40: Smartwatch i7 pro Max | D40: 1 | E40: Amigo higor | F40: Higor | G40: 60 | H40: 60 | I40: 70 | J40: 70 | K40: CPF | L40: 0.14285714 | M40: 10 | P40: Transferido
B41: 45322 | C41: Cabo Spartan v8 | D41: 1 | E41: Trabalho | F41: Leonardo | G41: 4.5 | H41: 4.5 | I41: 10 | J41: 10 | K41: CPF | L41: 0.55 | M41: 5.5 | P41: Transferido
A42: 2 | B42: 45324 | C42: tela mosquito leo | D42: 1 | E42: Deborah | F42: Leonardo | G42: 12 | H42: 12 | I42: 20 | J42: 20 | K42: CPF | L42: 0.4 | M42: 8 | P42: Transferido
A43: 2 | B43: 45325 | C43: Mini jogo de luz c/c | D43: 1 | E43: Aleatorio | F43: Leonardo | G43: 37 | H43: 37 | I43: 85 | J43: 85 | K43: CPF | L43: 0.56470588 | M43: 48 | P43: Transferido
A44: 2 | B44: 45325 | C44: Cabo kingo tc 1m | D44: 1 | E44: Aleatorio | F44: Rafael | G44: 7 | H44: 7 | I44: 12 | J44: 12 | K44: CPF | L44: 0.41666667 | M44: 5 | P44: Transferido
A45: 2 | B45: 45325 | C45: Powebank kv12047 10k | D45: 1 | E45: Aleatorio | F45: Rafael | G45: 55 | H45: 55 | I45: 80 | J45: 80 | K45: CPF | L45: 0.3125 | M45: 25 | P45: Transferido
A46: 2 | B46: 45327 | C46: Relógio inteligente KL201 Black | D46: 1 | E46: Aleatorio | F46: Higor | G46: 32.45 | H46: 32.45 | I46: 100 | J46: 100 | K46: CPF | L46: 0.6755 | M46: 67.55 | P46: Transferido
A47: 2 | B47: 45327 | C47: Powebank kv12047 10k | D47: 1 | E47: Aleatorio | F47: Higor | G47: 55 | H47: 55 | I47: 70 | J47: 70 | K47: CPF | L47: 0.21428571 | M47: 15 | P47: Transferido
A48: 2 | B48: 45327 | C48: Cabo Spartan v8 | D48: 1 | E48: Aleatorio | F48: Higor | G48: 4.5 | H48: 4.5 | I48: 8 | J48: 8 | K48: CPF | L48: 0.4375 | M48: 3.5 | P48: Transferido
A49: 2 | B49: 45329 | C49: pilha AAA cartela | D49: 1 | E49: Aleatorio | F49: Higor | G49: 1.2 | H49: 1.2 | I49: 5 | J49: 5 | K49: CPF | L49: 0.76 | M49: 3.8 | P49: Transferido
A50: 2 | B50: 45329 | C50: Cheirinho Hungria | D50: 1 | E50: Shopee CPF | F50: Leonardo | G50: 7.5 | H50: 7.5 | I50: 10.6 | J50: 10.6 | K50: Shopee | L50: 0.29245283 | M50: 3.1 | P50: Transferido
A51: 2 | B51: 45329 | C51: Garrafa Stanley 600lm | D51: 1 | E51: Shopee CPF | F51: Leonardo | G51: 35 | H51: 35 | I51: 63.3 | J51: 63.3 | K51: Shopee | L51: 0.44707741 | M51: 28.3 | P51: Transferido
A52: 2 | B52: 45329 | C52: Cheirinho Hungria | D52: 1 | E52: Shopee CPF | F52: Leonardo | G52: 7.5 | H52: 7.5 | I52: 10.6 | J52: 10.6 | K52: Shopee | L52: 0.29245283 | M52: 3.1 | P52: Transferido
A53: 2 | B53: 45329 | C53: Cheirinho Hungria | D53: 1 | E53: Shopee CPF | F53: Leonardo | G53: 7.5 | H53: 7.5 | I53: 10.6 | J53: 10.6 | K53: Shopee | L53: 0.29245283 | M53: 3.1 | P53: Transferido
A54: 2 | B54: 45329 | C54: Mini máquina de costura | D54: 1 | E54: Shopee | F54: Leonardo | G54: 7.5 | H54: 7.5 | I54: 16.89 | J54: 16.89 | K54: Shopee | L54: 0.55595027 | M54: 9.39 | P54: Transferido
A55: 2 | B55: 45329 | C55: Carregador iphone 20w | D55: 1 | E55: Beatriz almeida sales | F55: Leonardo | G55: 0 | H55: 0 | I55: 45 | J55: 45 | K55: CPF | L55: 1 | M55: 45 | P55: Transferido
A56: 2 | B56: 45329 | C56: Fone pmcell FO-15 | D56: 1 | E56: Shopee | F56: Leonardo | G56: 9 | H56: 9 | I56: 12 | J56: 12 | K56: CNPJ | L56: 0.25 | M56: 3 | P56: Transferido
A57: 2 | B57: 45329 | C57: pilha AAA cartela | D57: 1 | E57: Marcio | F57: Leonardo | G57: 1.2 | H57: 1.2 | I57: 5 | J57: 5 | K57: CPF | L57: 0.76 | M57: 3.8 | P57: Transferido
A58: 2 | B58: 45329 | C58: pilha AAA cartela | D58: 1 | E58: Marcio | F58: Leonardo | G58: 1.2 | H58: 1.2 | I58: 5 | J58: 5 | K58: CPF | L58: 0.76 | M58: 3.8 | P58: Transferido
A59: 2 | B59: 45329 | C59: pilha AA cartela | D59: 1 | E59: Marcio | F59: Leonardo | G59: 1.2 | H59: 1.2 | I59: 5 | J59: 5 | K59: CPF | L59: 0.76 | M59: 3.8 | P59: Transferido
A60: 2 | B60: 45329 | C60: pilha AA cartela | D60: 1 | E60: Marcio | F60: Leonardo | G60: 1.2 | H60: 1.2 | I60: 5 | J60: 5 | K60: CPF | L60: 0.76 | M60: 3.8 | P60: Transferido
A61: 2 | B61: 45329 | C61: Pendrive AL 16gb | D61: 1 | E61: Marcio | F61: Leonardo | G61: 13.5 | H61: 13.5 | I61: 25 | J61: 25 | K61: CPF | L61: 0.46 | M61: 11.5 | P61: Transferido
A62: 2 | B62: 45329 | C62: Suporte celular veicular ventosa bmg02 | D62: 1 | E62: Matheus | F62: Leonardo | G62: 10 | H62: 10 | I62: 25 | J62: 25 | K62: CPF | L62: 0.6 | M62: 15 | P62: Transferido
A63: 2 | B63: 45329 | C63: Carregador veicular inova tc | D63: 1 | E63: Matheus | F63: Leonardo | G63: 11 | H63: 11 | I63: 25 | J63: 25 | K63: CPF | L63: 0.56 | M63: 14 | P63: Transferido
A64: 2 | B64: 45330 | C64: Suporte magnético veicular barra | D64: 1 | E64: Aleatorio | F64: Higor | G64: 6 | H64: 6 | I64: 8 | J64: 8 | K64: CPF | L64: 0.25 | M64: 2 | P64: Transferido
A65: 2 | B65: 45330 | C65: Adaptador wifi 2.5g | D65: 1 | E65: Marcio | F65: Leonardo | G65: 11 | H65: 11 | I65: 25 | J65: 25 | K65: CPF | L65: 0.56 | M65: 14 | P65: Transferido
A66: 2 | B66: 45330 | C66: Adaptador wifi 2.5g antena | D66: 1 | E66: Marcio | F66: Leonardo | G66: 12 | H66: 12 | I66: 30 | J66: 30 | K66: CPF | L66: 0.6 | M66: 18 | P66: Transferido
...

Sheet Vendas 2025
A1: Mês | B1: Data | C1: Produto | D1: QT | E1: Cliente | F1: Vendedor | G1: Custo Un | H1: Valor gasto | I1: Valor uni venda | J1: Valor da venda | K1: Tipo de venda | L1: Valor CNPJ | M1: Lucro | N1: Forma de pagam | O1: % Lucro | P1: Recebido loja
A2: 1 | B2: 45659 | C2: Fonte 12v | D2: 1 | E2: hugo Som | F2: Fisica | G2: 10 | H2: 10 | I2: 15 | J2: 15 | K2: cpf | L2: 0.33333333 | M2: 5 | P2: Transferido
A3: 1 | B3: 45659 | C3: impressao preta | D3: 1 | E3: senhor loja | F3: Fisica | G3: 0.07 | H3: 0.07 | I3: 1 | J3: 1 | K3: cpf | L3: 0.93 | M3: 0.93 | P3: Transferido
A4: 1 | B4: 45659 | C4: Serviço Aleatorio | D4: 1 | E4: Aleatorio | F4: Fisica | G4: 0 | H4: 0 | I4: 10 | J4: 10 | K4: cpf | L4: 1 | M4: 10 | P4: Transferido
A5: 1 | B5: 45659 | C5: adaptador bluetooth | D5: 1 | E5: cliente israel | F5: Fisica | G5: 5 | H5: 5 | I5: 20 | J5: 20 | K5: cpf | L5: 0.75 | M5: 15 | P5: Transferido
A6: 1 | B6: 45659 | C6: Controle wireless gamepad alto-4w | D6: 1 | E6: cliente israel | F6: Fisica | G6: 63 | H6: 63 | I6: 110 | J6: 110 | K6: cpf | L6: 0.42727273 | M6: 47 | P6: Transferido
A7: 1 | B7: 45660 | C7: impressao preta | D7: 5 | E7: Aleatorio | F7: Fisica | G7: 0.07 | H7: 0.35 | I7: 1 | J7: 5 | K7: cpf | L7: 0.93 | M7: 4.65 | P7: Transferido
A8: 1 | B8: 45660 | C8: pelicula 3d | D8: 1 | E8: Aleatorio | F8: Fisica | G8: 3 | H8: 3 | I8: 15 | J8: 15 | K8: cpf | L8: 0.8 | M8: 12 | P8: Transferido
A9: 1 | B9: 45660 | C9: Serviço Aleatorio | D9: 1 | E9: Aleatorio | F9: Fisica | G9: 0 | H9: 0 | I9: 29 | J9: 29 | K9: cpf | L9: 1 | M9: 29 | P9: Transferido
A10: 1 | B10: 45660 | C10: pelicula 3d | D10: 2 | E10: Aleatorio | F10: Fisica | G10: 3 | H10: 6 | I10: 15 | J10: 30 | K10: cpf | L10: 0.8 | M10: 24 | P10: Transferido
A11: 1 | B11: 45660 | C11: capinha | D11: 2 | E11: Aleatorio | F11: Fisica | G11: 3 | H11: 6 | I11: 15 | J11: 30 | K11: cpf | L11: 0.8 | M11: 24 | P11: Transferido
A12: 1 | B12: 45661 | C12: luvinha de dedo | D12: 2 | E12: Aleatorio | F12: Fisica | G12: 0 | H12: 0 | I12: 5 | J12: 10 | K12: cpf | L12: 1 | M12: 10 | P12: Transferido
A13: 1 | B13: 45663 | C13: impressao preta | D13: 2 | E13: Cliente Impressão João Pedro | F13: Fisica | G13: 0.07 | H13: 0.14 | I13: 1 | J13: 2 | K13: cpf | L13: 0.93 | M13: 1.86 | P13: Transferido
A14: 1 | B14: 45663 | C14: Formatação | D14: 1 | E14: Cliente Pc Ronei | F14: Fisica | G14: 0 | H14: 0 | I14: 60 | J14: 60 | K14: cpf | L14: 1 | M14: 60 | P14: Transferido
A15: 1 | B15: 45663 | C15: impressao preta | D15: 2 | E15: Cliente mateus impressao | F15: Fisica | G15: 0.07 | H15: 0.14 | I15: 1 | J15: 2 | K15: cpf | L15: 0.93 | M15: 1.86 | P15: Transferido
A16: 1 | B16: 45663 | C16: Serviço Aleatorio | D16: 1 | E16: Aleatorio | F16: Fisica | G16: 0 | H16: 0 | I16: 5 | J16: 5 | K16: cpf | L16: 1 | M16: 5 | P16: Transferido
A17: 1 | B17: 45664 | C17: impressao preta | D17: 3 | E17: Aleatorio | F17: Fisica | G17: 0.07 | H17: 0.21 | I17: 1 | J17: 3 | K17: cpf | L17: 0.93 | M17: 2.79 | P17: Transferido
A18: 1 | B18: 45664 | C18: impressao preta | D18: 1 | E18: hugo Som | F18: Fisica | G18: 0.07 | H18: 0.07 | I18: 1 | J18: 1 | K18: cpf | L18: 0.93 | M18: 0.93 | P18: Transferido
A19: 1 | B19: 45664 | C19: chip com recarga | D19: 2 | E19: Aleatorio | F19: Fisica | G19: 0 | H19: 0 | I19: 30 | J19: 60 | K19: cpf | L19: 1 | M19: 60 | P19: Transferido
A20: 1 | B20: 45664 | C20: manutençao | D20: 1 | E20: Aleatorio | F20: luiz | G20: 0 | H20: 0 | I20: 37.5 | J20: 37.5 | K20: cpf | L20: 1 | M20: 37.5 | P20: Transferido
A21: 1 | B21: 45664 | C21: Serviço Aleatorio | D21: 1 | E21: Aleatorio | F21: luiz | G21: 0 | H21: 0 | I21: 150 | J21: 150 | K21: cpf | L21: 0.35 | M21: 150 | P21: Transferido
A22: 1 | B22: 45664 | C22: Pendrive 16gb AL-U-16 | D22: 1 | E22: luiz | F22: Fisica | G22: 13 | H22: 13 | I22: 20 | J22: 20 | K22: cpf | L22: 0.73333333 | M22: 7 | P22: Transferido
A23: 1 | B23: 45664 | C23: PILHA FLEX AAA | D23: 1 | E23: Aleatorio | F23: Fisica | G23: 4 | H23: 4 | I23: 15 | J23: 15 | K23: cpf | L23: 0.93 | M23: 11 | P23: Transferido
A24: 1 | B24: 45665 | C24: impressao preta | D24: 5 | E24: hugo Som | F24: Fisica | G24: 0.07 | H24: 0.35 | I24: 1 | J24: 5 | K24: cpf | L24: 1 | M24: 4.65 | P24: Transferido
A25: 1 | B25: 45665 | C25: pelicula 3d | D25: 1 | E25: Aleatorio | F25: Fisica | G25: 3 | H25: 3 | I25: 15 | J25: 15 | K25: cpf | L25: 0.8 | M25: 12 | P25: Transferido
A26: 1 | B26: 45665 | C26: Cabo auxiliar p2 LE-804 | D26: 1 | E26: RELOGIO | F26: Fisica | G26: 2.5 | H26: 2.5 | I26: 10 | J26: 10 | L26: 0.75 | M26: 7.5 | P26: Transferido
A27: 1 | B27: 45666 | C27: impressao preta | D27: 1 | E27: senhor | F27: Fisica | G27: 0.07 | H27: 0.07 | I27: 1 | J27: 1 | K27: cpf | L27: 0.93 | M27: 0.93 | P27: Transferido
A28: 1 | B28: 45666 | C28: luvinha de dedo | D28: 2 | E28: Aleatorio | F28: Fisica | G28: 0 | H28: 0 | I28: 5 | J28: 10 | K28: cpf | L28: 1 | M28: 10 | P28: Transferido
A29: 1 | B29: 45667 | C29: Carregador tipo c 4.1 LE-497 | D29: 1 | E29: Aleatorio | F29: Fisica | G29: 10 | H29: 10 | I29: 30 | J29: 30 | K29: cpf | L29: 0.66666667 | M29: 20 | P29: Transferido
A30: 1 | B30: 45668 | C30: Cabo Kingo Iphone 1M | D30: 1 | E30: fernando | F30: Fisica | G30: 7 | H30: 7 | I30: 20 | J30: 20 | K30: cpf | L30: 0.65 | M30: 13 | P30: Transferido
A31: 1 | B31: 45671 | C31: impressao preta | D31: 5 | E31: hugo Som | F31: Fisica | G31: 0.07 | H31: 0.35 | I31: 1 | J31: 5 | K31: cpf | L31: 0.93 | M31: 4.65 | P31: Transferido
A32: 1 | B32: 45671 | C32: impressao preta | D32: 1 | E32: Aleatorio | F32: Fisica | G32: 0.07 | H32: 0.07 | I32: 1 | J32: 1 | K32: cpf | L32: 0.93 | M32: 0.93 | P32: Transferido
A33: 1 | B33: 45671 | C33: Bateria 2032 | D33: 1 | E33: Aleatorio | F33: Fisica | G33: 1 | H33: 1 | I33: 5 | J33: 5 | K33: cpf | L33: 0.8 | M33: 4 | P33: Transferido
A34: 1 | B34: 45672 | C34: impressao preta | D34: 2 | E34: Aleatorio | F34: Fisica | G34: 0.07 | H34: 0.14 | I34: 1 | J34: 2 | K34: cpf | L34: 0.93 | M34: 1.86 | P34: Transferido
A35: 1 | B35: 45672 | C35: impressao preta | D35: 9 | E35: Aleatorio | F35: Fisica | G35: 0.07 | H35: 0.63 | I35: 1 | J35: 9 | K35: cpf | L35: 0.93 | M35: 8.37 | P35: Transferido
A36: 1 | B36: 45672 | C36: Fonte notebook grasep | D36: 1 | E36: Diretora higor | F36: Fisica | G36: 32 | H36: 32 | I36: 70 | J36: 70 | K36: cpf | L36: 0.54285714 | M36: 38 | P36: Transferido
A37: 1 | B37: 45672 | C37: Envelope A4 | D37: 1 | E37: Aleatorio | F37: Fisica | G37: 0.3955 | H37: 0.3955 | I37: 1 | J37: 1 | K37: cpf | L37: 0.6045 | M37: 0.6045 | P37: Transferido
A38: 1 | B38: 45672 | C38: Escova magica | D38: 2 | E38: leandro | F38: Fisica | G38: 25 | H38: 50 | I38: 50 | J38: 100 | K38: cpf | L38: 0.5 | M38: 50 | P38: Transferido
A39: 1 | B39: 45672 | C39: manutençao | D39: 1 | E39: Diretora higor | F39: luiz | G39: 0 | H39: 0 | I39: 50 | J39: 50 | K39: cpf | L39: 1 | M39: 50 | P39: Transferido
A40: 1 | B40: 45672 | C40: Suporte Moto Le-030D | D40: 1 | E40: Aleatorio | F40: Fisica | G40: 16 | H40: 16 | I40: 35 | J40: 35 | K40: cpf | L40: 0.54285714 | M40: 19 | P40: Transferido
...

Sheet Vendas 2026
A1: Mês | B1: Data | C1: Produto | D1: QT | E1: Cliente | F1: Vendedor | G1: Custo Un | H1: Valor gasto | I1: Valor uni venda | J1: entrada | K1: Valor da venda | L1: Lucro | M1: Coluna2 | N1: Recebido loja | O1: Coluna1 | S1: valor anuncio | T1: valor desocnto | U1: valor recebido | V1: Valor da taxa | W1: valor a pagar | X1: lucro
A2: =IF(Table_246[[#This Row],[Data]]="","",MONTH(Table_246[[#This Row],[Data]])) -> 1 | B2: 46024 | C2: Carregador Completo Iphone 20W | D2: 1 | E2: elza | F2: Fisica | G2: 12 | H2: =Table_246[[#This Row],[QT]]*Table_246[[#This Row],[Custo Un]] -> 12 | I2: 30 | J2: =I2*D2 -> 30 | K2: =I2*D2 -> 30 | L2: =Table_246[[#This Row],[Valor da venda]]-Table_246[[#This Row],[Valor gasto]] -> 18 | M2: =IFERROR(L2/K2, 0) -> 0.6 | N2: Transferido | O2: =IF([1]!Table_246[[#This Row],[Coluna2]]>0.5, "🔥 Excelente", IF([1]!Table_246[[#This Row],[Coluna2]]>0.4, "👍 Bom", "⚠️ Baixo")) -> 🔥 Excelente | R2: 600 | S2: 725 | T2: 0.25 | U2: =S2-(S2*T2)-4 -> 539.75 | V2: =S2*25% -> 181.25 | W2: 490 | X2: =U2-W2 -> 49.75
A3: =IF(Table_246[[#This Row],[Data]]="","",MONTH(Table_246[[#This Row],[Data]])) -> 1 | B3: 46027 | C3: Pelicula 3D | D3: 1 | E3: vall | F3: Fisica | G3: =IFERROR(VLOOKUP(C3,PROD!$A$2:$E$1204,5,0),"0") -> 3 | H3: =Table_246[[#This Row],[QT]]*Table_246[[#This Row],[Custo Un]] -> 3 | I3: 15 | J3: =I3*D3 -> 15 | K3: =I3*D3 -> 15 | L3: =Table_246[[#This Row],[Valor da venda]]-Table_246[[#This Row],[Valor gasto]] -> 12 | M3: =IFERROR(L3/K3, 0) -> 0.8 | N3: Transferido | O3: =IF([1]!Table_246[[#This Row],[Coluna2]]>0.5, "🔥 Excelente", IF([1]!Table_246[[#This Row],[Coluna2]]>0.4, "👍 Bom", "⚠️ Baixo")) -> 🔥 Excelente | R3: 800 | S3: 830 | T3: 0.25 | U3: =S3-(S3*T3)-4 -> 618.5 | V3: =S3*25% -> 207.5 | W3: 550 | X3: =U3-W3 -> 68.5
A4: =IF(Table_246[[#This Row],[Data]]="","",MONTH(Table_246[[#This Row],[Data]])) -> 1 | B4: 46027 | C4: Cheirinho | D4: 2 | E4: 26010470HA378U | F4: Shopee | G4: 7.5 | H4: =Table_246[[#This Row],[QT]]*Table_246[[#This Row],[Custo Un]] -> 15 | I4: 28.1 | J4: =I4*D4 -> 56.2 | K4: =I4*D4 -> 56.2 | L4: =Table_246[[#This Row],[Valor da venda]]-Table_246[[#This Row],[Valor gasto]] -> 41.2 | M4: =IFERROR(L4/K4, 0) -> 0.73309609 | N4: Transferido | O4: =IF([1]!Table_246[[#This Row],[Coluna2]]>0.5, "🔥 Excelente", IF([1]!Table_246[[#This Row],[Coluna2]]>0.4, "👍 Bom", "⚠️ Baixo")) -> 🔥 Excelente | R4: 900 | S4: 800 | T4: 0.25 | U4: =S4-(S4*T4)-4 -> 596 | V4: =S4*25% -> 200 | W4: 510 | X4: =U4-W4 -> 86
A5: =IF(Table_246[[#This Row],[Data]]="","",MONTH(Table_246[[#This Row],[Data]])) -> 1 | B5: 46027 | C5: Nterruptor De Controle Remoto | D5: 1 | E5: 2601057PDHKMGS | F5: Shopee | G5: 15 | H5: =Table_246[[#This Row],[QT]]*Table_246[[#This Row],[Custo Un]] -> 15 | I5: 41.6 | J5: =I5*D5 -> 41.6 | K5: =I5*D5 -> 41.6 | L5: =Table_246[[#This Row],[Valor da venda]]-Table_246[[#This Row],[Valor gasto]] -> 26.6 | M5: =IFERROR(L5/K5, 0) -> 0.63942308 | N5: Transferido | O5: =IF([1]!Table_246[[#This Row],[Coluna2]]>0.5, "🔥 Excelente", IF([1]!Table_246[[#This Row],[Coluna2]]>0.4, "👍 Bom", "⚠️ Baixo")) -> 🔥 Excelente | R5: 1000 | S5: 1000 | T5: 0.25 | U5: =S5-(S5*T5)-4 -> 746 | V5: =S5*25% -> 250 | W5: 700 | X5: =U5-W5 -> 46
A6: =IF(Table_246[[#This Row],[Data]]="","",MONTH(Table_246[[#This Row],[Data]])) -> 1 | B6: 46027 | C6: Desentupidor | D6: 1 | E6: 26010322KX6CM7 | F6: Shopee | G6: 12 | H6: =Table_246[[#This Row],[QT]]*Table_246[[#This Row],[Custo Un]] -> 12 | I6: 14.99 | J6: =I6*D6 -> 14.99 | K6: =I6*D6 -> 14.99 | L6: =Table_246[[#This Row],[Valor da venda]]-Table_246[[#This Row],[Valor gasto]] -> 2.99 | M6: =IFERROR(L6/K6, 0) -> 0.19946631 | N6: Transferido | O6: =IF([1]!Table_246[[#This Row],[Coluna2]]>0.5, "🔥 Excelente", IF([1]!Table_246[[#This Row],[Coluna2]]>0.4, "👍 Bom", "⚠️ Baixo")) -> ⚠️ Baixo | S6: 36 | T6: 0.25 | U6: =S6-(S6*T6)-4 -> 23 | V6: =S6*25% -> 9 | X6: =U6-W6 -> 23
A7: =IF(Table_246[[#This Row],[Data]]="","",MONTH(Table_246[[#This Row],[Data]])) -> 1 | B7: 46027 | C7: Desentupidor | D7: 1 | E7: 26010321EYMMGF | F7: Shopee | G7: 12 | H7: =Table_246[[#This Row],[QT]]*Table_246[[#This Row],[Custo Un]] -> 12 | I7: 14.99 | J7: =I7*D7 -> 14.99 | K7: =I7*D7 -> 14.99 | L7: =Table_246[[#This Row],[Valor da venda]]-Table_246[[#This Row],[Valor gasto]] -> 2.99 | M7: =IFERROR(L7/K7, 0) -> 0.19946631 | N7: Transferido | O7: =IF([1]!Table_246[[#This Row],[Coluna2]]>0.5, "🔥 Excelente", IF([1]!Table_246[[#This Row],[Coluna2]]>0.4, "👍 Bom", "⚠️ Baixo")) -> ⚠️ Baixo | R7: 520 | S7: 520 | T7: 0.23 | U7: =S7-(S7*T7)-4 -> 396.4 | V7: =S7*25% -> 130 | W7: 350 | X7: =U7-W7 -> 46.4
A8: =IF(Table_246[[#This Row],[Data]]="","",MONTH(Table_246[[#This Row],[Data]])) -> 1 | B8: 46027 | C8: Case 2.5 Hd | D8: 1 | E8: 26010330Y0QYCC | F8: Shopee | G8: 19 | H8: =Table_246[[#This Row],[QT]]*Table_246[[#This Row],[Custo Un]] -> 19 | I8: 34.75 | J8: =I8*D8 -> 34.75 | K8: =I8*D8 -> 34.75 | L8: =Table_246[[#This Row],[Valor da venda]]-Table_246[[#This Row],[Valor gasto]] -> 15.75 | M8: =IFERROR(L8/K8, 0) -> 0.45323741 | N8: Transferido | O8: =IF([1]!Table_246[[#This Row],[Coluna2]]>0.5, "🔥 Excelente", IF([1]!Table_246[[#This Row],[Coluna2]]>0.4, "👍 Bom", "⚠️ Baixo")) -> 👍 Bom | S8: 820 | T8: 0.21 | U8: =S8-(S8*T8)-4 -> 643.8 | V8: =S8*25% -> 205 | W8: 550 | X8: =U8-W8 -> 93.8
A9: =IF(Table_246[[#This Row],[Data]]="","",MONTH(Table_246[[#This Row],[Data]])) -> 1 | B9: 46027 | C9: Pelicula 3D | D9: 1 | E9: vall | F9: Fisica | G9: 6 | H9: =Table_246[[#This Row],[QT]]*Table_246[[#This Row],[Custo Un]] -> 6 | I9: 15 | J9: =I9*D9 -> 15 | K9: =I9*D9 -> 15 | L9: =Table_246[[#This Row],[Valor da venda]]-Table_246[[#This Row],[Valor gasto]] -> 9 | M9: =IFERROR(L9/K9, 0) -> 0.6 | N9: Transferido | O9: =IF([1]!Table_246[[#This Row],[Coluna2]]>0.5, "🔥 Excelente", IF([1]!Table_246[[#This Row],[Coluna2]]>0.4, "👍 Bom", "⚠️ Baixo")) -> 🔥 Excelente | R9: usina | S9: 800 | T9: 0.23 | U9: =S9-(S9*T9)-4 -> 612 | V9: =S9*25% -> 200 | W9: 570 | X9: =U9-W9 -> 42
A10: =IF(Table_246[[#This Row],[Data]]="","",MONTH(Table_246[[#This Row],[Data]])) -> 1 | B10: 46028 | C10: Pelicula 3D | D10: 1 | E10: boneca | F10: Fisica | G10: =IFERROR(VLOOKUP(C10,PROD!$A$2:$E$1204,5,0),"0") -> 3 | H10: =Table_246[[#This Row],[QT]]*Table_246[[#This Row],[Custo Un]] -> 3 | I10: 15 | J10: =I10*D10 -> 15 | K10: =I10*D10 -> 15 | L10: =Table_246[[#This Row],[Valor da venda]]-Table_246[[#This Row],[Valor gasto]] -> 12 | M10: =IFERROR(L10/K10, 0) -> 0.8 | N10: Transferido | O10: =IF([1]!Table_246[[#This Row],[Coluna2]]>0.5, "🔥 Excelente", IF([1]!Table_246[[#This Row],[Coluna2]]>0.4, "👍 Bom", "⚠️ Baixo")) -> 🔥 Excelente | S10: 10 | T10: 0.23 | U10: =S10-(S10*T10)-4 -> 3.7 | V10: =S10*25% -> 2.5 | X10: =U10-W10 -> 3.7
A11: =IF(Table_246[[#This Row],[Data]]="","",MONTH(Table_246[[#This Row],[Data]])) -> 1 | B11: 46028 | C11: Restauraçao Dados | D11: 1 | E11: Eliane | F11: Fisica | G11: =IFERROR(VLOOKUP(C11,PROD!$A$2:$E$1204,5,0),"0") -> 0 | H11: =Table_246[[#This Row],[QT]]*Table_246[[#This Row],[Custo Un]] -> 0 | I11: 100 | J11: =I11*D11 -> 100 | K11: =I11*D11 -> 100 | L11: =Table_246[[#This Row],[Valor da venda]]-Table_246[[#This Row],[Valor gasto]] -> 100 | M11: =IFERROR(L11/K11, 0) -> 1 | N11: Transferido | O11: =IF([1]!Table_246[[#This Row],[Coluna2]]>0.5, "🔥 Excelente", IF([1]!Table_246[[#This Row],[Coluna2]]>0.4, "👍 Bom", "⚠️ Baixo")) -> 🔥 Excelente | S11: 12 | T11: 0.23 | U11: =S11-(S11*T11)-4 -> 5.24 | V11: =S11*25% -> 3 | X11: =U11-W11 -> 5.24
A12: =IF(Table_246[[#This Row],[Data]]="","",MONTH(Table_246[[#This Row],[Data]])) -> 1 | B12: 46029 | C12: Gravação De Musica | D12: 1 | E12: aleatorio | F12: Fisica | G12: =IFERROR(VLOOKUP(C12,PROD!$A$2:$E$1204,5,0),"0") -> 0 | H12: =Table_246[[#This Row],[QT]]*Table_246[[#This Row],[Custo Un]] -> 0 | I12: 15 | J12: =I12*D12 -> 15 | K12: =I12*D12 -> 15 | L12: =Table_246[[#This Row],[Valor da venda]]-Table_246[[#This Row],[Valor gasto]] -> 15 | M12: =IFERROR(L12/K12, 0) -> 1 | N12: Transferido | O12: =IF([1]!Table_246[[#This Row],[Coluna2]]>0.5, "🔥 Excelente", IF([1]!Table_246[[#This Row],[Coluna2]]>0.4, "👍 Bom", "⚠️ Baixo")) -> 🔥 Excelente | S12: 20 | T12: 0.23 | U12: =S12-(S12*T12)-4 -> 11.4 | V12: =S12*25% -> 5 | X12: =U12-W12 -> 11.4
A13: =IF(Table_246[[#This Row],[Data]]="","",MONTH(Table_246[[#This Row],[Data]])) -> 1 | B13: 46029 | C13: Boneco Lego Kit | D13: 1 | E13: aleatorio | F13: Fisica | G13: 11 | H13: =Table_246[[#This Row],[QT]]*Table_246[[#This Row],[Custo Un]] -> 11 | I13: 20 | J13: =I13*D13 -> 20 | K13: =I13*D13 -> 20 | L13: =Table_246[[#This Row],[Valor da venda]]-Table_246[[#This Row],[Valor gasto]] -> 9 | M13: =IFERROR(L13/K13, 0) -> 0.45 | N13: Transferido | O13: =IF([1]!Table_246[[#This Row],[Coluna2]]>0.5, "🔥 Excelente", IF([1]!Table_246[[#This Row],[Coluna2]]>0.4, "👍 Bom", "⚠️ Baixo")) -> 👍 Bom | T13: 0.23 | U13: =S13-(S13*T13)-4 -> -4 | V13: =S13*25% -> 0 | X13: =U13-W13 -> -4
A14: =IF(Table_246[[#This Row],[Data]]="","",MONTH(Table_246[[#This Row],[Data]])) -> 1 | B14: 46034 | C14: Impressao Preta | D14: 1 | E14: sonia | F14: Fisica | G14: =IFERROR(VLOOKUP(C14,PROD!$A$2:$E$1204,5,0),"0") -> 0.07 | H14: =Table_246[[#This Row],[QT]]*Table_246[[#This Row],[Custo Un]] -> 0.07 | I14: 1 | J14: =I14*D14 -> 1 | K14: =I14*D14 -> 1 | L14: =Table_246[[#This Row],[Valor da venda]]-Table_246[[#This Row],[Valor gasto]] -> 0.93 | M14: =IFERROR(L14/K14, 0) -> 0.93 | N14: Transferido | O14: =IF([1]!Table_246[[#This Row],[Coluna2]]>0.5, "🔥 Excelente", IF([1]!Table_246[[#This Row],[Coluna2]]>0.4, "👍 Bom", "⚠️ Baixo")) -> 🔥 Excelente | T14: 0.23 | U14: =S14-(S14*T14)-4 -> -4 | V14: =S14*25% -> 0 | X14: =U14-W14 -> -4
A15: =IF(Table_246[[#This Row],[Data]]="","",MONTH(Table_246[[#This Row],[Data]])) -> 1 | B15: 46034 | C15: Durex | D15: 1 | E15: cacheados | F15: Fisica | G15: =IFERROR(VLOOKUP(C15,PROD!$A$2:$E$1204,5,0),"0") -> 2.5 | H15: =Table_246[[#This Row],[QT]]*Table_246[[#This Row],[Custo Un]] -> 2.5 | I15: 7 | J15: =I15*D15 -> 7 | K15: =I15*D15 -> 7 | L15: =Table_246[[#This Row],[Valor da venda]]-Table_246[[#This Row],[Valor gasto]] -> 4.5 | M15: =IFERROR(L15/K15, 0) -> 0.64285714 | N15: Transferido | O15: =IF([1]!Table_246[[#This Row],[Coluna2]]>0.5, "🔥 Excelente", IF([1]!Table_246[[#This Row],[Coluna2]]>0.4, "👍 Bom", "⚠️ Baixo")) -> 🔥 Excelente
A16: =IF(Table_246[[#This Row],[Data]]="","",MONTH(Table_246[[#This Row],[Data]])) -> 1 | B16: 46034 | C16: Moeba | D16: 1 | E16: samuel | F16: Fisica | G16: 5 | H16: =Table_246[[#This Row],[QT]]*Table_246[[#This Row],[Custo Un]] -> 5 | I16: 10 | J16: =I16*D16 -> 10 | K16: =I16*D16 -> 10 | L16: =Table_246[[#This Row],[Valor da venda]]-Table_246[[#This Row],[Valor gasto]] -> 5 | M16: =IFERROR(L16/K16, 0) -> 0.5 | N16: Transferido | O16: =IF([1]!Table_246[[#This Row],[Coluna2]]>0.5, "🔥 Excelente", IF([1]!Table_246[[#This Row],[Coluna2]]>0.4, "👍 Bom", "⚠️ Baixo")) -> 👍 Bom
A17: =IF(Table_246[[#This Row],[Data]]="","",MONTH(Table_246[[#This Row],[Data]])) -> 1 | B17: 46034 | C17: Impressao Preta | D17: 4 | E17: aleatorio | F17: Fisica | G17: =IFERROR(VLOOKUP(C17,PROD!$A$2:$E$1204,5,0),"0") -> 0.07 | H17: =Table_246[[#This Row],[QT]]*Table_246[[#This Row],[Custo Un]] -> 0.28 | I17: 1 | J17: =I17*D17 -> 4 | K17: =I17*D17 -> 4 | L17: =Table_246[[#This Row],[Valor da venda]]-Table_246[[#This Row],[Valor gasto]] -> 3.72 | M17: =IFERROR(L17/K17, 0) -> 0.93 | N17: Transferido | O17: =IF([1]!Table_246[[#This Row],[Coluna2]]>0.5, "🔥 Excelente", IF([1]!Table_246[[#This Row],[Coluna2]]>0.4, "👍 Bom", "⚠️ Baixo")) -> 🔥 Excelente
A18: =IF(Table_246[[#This Row],[Data]]="","",MONTH(Table_246[[#This Row],[Data]])) -> 1 | B18: 46034 | C18: Cheirinho Para Carro | D18: 2 | E18: 260113UN53PDB3 | F18: Shopee | G18: 7.5 | H18: =Table_246[[#This Row],[QT]]*Table_246[[#This Row],[Custo Un]] -> 15 | I18: 14.05 | J18: =I18*D18 -> 28.1 | K18: =I18*D18 -> 28.1 | L18: =Table_246[[#This Row],[Valor da venda]]-Table_246[[#This Row],[Valor gasto]] -> 13.1 | M18: =IFERROR(L18/K18, 0) -> 0.46619217 | N18: Transferido | O18: =IF([1]!Table_246[[#This Row],[Coluna2]]>0.5, "🔥 Excelente", IF([1]!Table_246[[#This Row],[Coluna2]]>0.4, "👍 Bom", "⚠️ Baixo")) -> 👍 Bom
A19: =IF(Table_246[[#This Row],[Data]]="","",MONTH(Table_246[[#This Row],[Data]])) -> 1 | B19: 46034 | C19: Pen Drive Com 10 Jogos Para Ps2 | D19: 1 | E19: 1732942733137053663 | F19: Tiktok | G19: =IFERROR(VLOOKUP(C19,PROD!$A$2:$E$1204,5,0),"0") -> 0 | H19: =Table_246[[#This Row],[QT]]*Table_246[[#This Row],[Custo Un]] -> 0 | I19: 100.32 | J19: =I19*D19 -> 100.32 | K19: =I19*D19 -> 100.32 | L19: =Table_246[[#This Row],[Valor da venda]]-Table_246[[#This Row],[Valor gasto]] -> 100.32 | M19: =IFERROR(L19/K19, 0) -> 1 | N19: Transferido | O19: =IF([1]!Table_246[[#This Row],[Coluna2]]>0.5, "🔥 Excelente", IF([1]!Table_246[[#This Row],[Coluna2]]>0.4, "👍 Bom", "⚠️ Baixo")) -> 🔥 Excelente
A20: =IF(Table_246[[#This Row],[Data]]="","",MONTH(Table_246[[#This Row],[Data]])) -> 1 | B20: 46035 | C20: Impressao Preta | D20: 1 | E20: samuel | F20: Fisica | G20: =IFERROR(VLOOKUP(C20,PROD!$A$2:$E$1204,5,0),"0") -> 0.07 | H20: =Table_246[[#This Row],[QT]]*Table_246[[#This Row],[Custo Un]] -> 0.07 | I20: 1 | J20: =I20*D20 -> 1 | K20: =I20*D20 -> 1 | L20: =Table_246[[#This Row],[Valor da venda]]-Table_246[[#This Row],[Valor gasto]] -> 0.93 | M20: =IFERROR(L20/K20, 0) -> 0.93 | N20: Transferido | O20: =IF([1]!Table_246[[#This Row],[Coluna2]]>0.5, "🔥 Excelente", IF([1]!Table_246[[#This Row],[Coluna2]]>0.4, "👍 Bom", "⚠️ Baixo")) -> 🔥 Excelente
A21: =IF(Table_246[[#This Row],[Data]]="","",MONTH(Table_246[[#This Row],[Data]])) -> 1 | B21: 46035 | C21: Impressao Preta | D21: 4 | E21: eliane | F21: Fisica | G21: =IFERROR(VLOOKUP(C21,PROD!$A$2:$E$1204,5,0),"0") -> 0.07 | H21: =Table_246[[#This Row],[QT]]*Table_246[[#This Row],[Custo Un]] -> 0.28 | I21: 1 | J21: =I21*D21 -> 4 | K21: =I21*D21 -> 4 | L21: =Table_246[[#This Row],[Valor da venda]]-Table_246[[#This Row],[Valor gasto]] -> 3.72 | M21: =IFERROR(L21/K21, 0) -> 0.93 | N21: Transferido | O21: =IF([1]!Table_246[[#This Row],[Coluna2]]>0.5, "🔥 Excelente", IF([1]!Table_246[[#This Row],[Coluna2]]>0.4, "👍 Bom", "⚠️ Baixo")) -> 🔥 Excelente
A22: =IF(Table_246[[#This Row],[Data]]="","",MONTH(Table_246[[#This Row],[Data]])) -> 1 | B22: 46036 | C22: Protetor Documento | D22: 1 | E22: 26011533GTJVCC | F22: Shopee | G22: 3 | H22: =Table_246[[#This Row],[QT]]*Table_246[[#This Row],[Custo Un]] -> 3 | I22: 4.54 | J22: =I22*D22 -> 4.54 | K22: =I22*D22 -> 4.54 | L22: =Table_246[[#This Row],[Valor da venda]]-Table_246[[#This Row],[Valor gasto]] -> 1.54 | M22: =IFERROR(L22/K22, 0) -> 0.33920705 | N22: Transferido | O22: =IF([1]!Table_246[[#This Row],[Coluna2]]>0.5, "🔥 Excelente", IF([1]!Table_246[[#This Row],[Coluna2]]>0.4, "👍 Bom", "⚠️ Baixo")) -> ⚠️ Baixo
A23: =IF(Table_246[[#This Row],[Data]]="","",MONTH(Table_246[[#This Row],[Data]])) -> 1 | B23: 46036 | C23: Kit Maçarico | D23: 1 | E23: 260115363HXRNS | F23: Shopee | G23: 25 | H23: =Table_246[[#This Row],[QT]]*Table_246[[#This Row],[Custo Un]] -> 25 | I23: 52.99 | J23: =I23*D23 -> 52.99 | K23: =I23*D23 -> 52.99 | L23: =Table_246[[#This Row],[Valor da venda]]-Table_246[[#This Row],[Valor gasto]] -> 27.99 | M23: =IFERROR(L23/K23, 0) -> 0.52821287 | N23: Transferido | O23: =IF([1]!Table_246[[#This Row],[Coluna2]]>0.5, "🔥 Excelente", IF([1]!Table_246[[#This Row],[Coluna2]]>0.4, "👍 Bom", "⚠️ Baixo")) -> 🔥 Excelente
A24: =IF(Table_246[[#This Row],[Data]]="","",MONTH(Table_246[[#This Row],[Data]])) -> 1 | B24: 46037 | C24: Pelicula 3D | D24: 1 | E24: aleatorio | F24: Fisica | G24: =IFERROR(VLOOKUP(C24,PROD!$A$2:$E$1204,5,0),"0") -> 3 | H24: =Table_246[[#This Row],[QT]]*Table_246[[#This Row],[Custo Un]] -> 3 | I24: 10 | J24: =I24*D24 -> 10 | K24: =I24*D24 -> 10 | L24: =Table_246[[#This Row],[Valor da venda]]-Table_246[[#This Row],[Valor gasto]] -> 7 | M24: =IFERROR(L24/K24, 0) -> 0.7 | N24: Transferido | O24: =IF([1]!Table_246[[#This Row],[Coluna2]]>0.5, "🔥 Excelente", IF([1]!Table_246[[#This Row],[Coluna2]]>0.4, "👍 Bom", "⚠️ Baixo")) -> 🔥 Excelente
A25: =IF(Table_246[[#This Row],[Data]]="","",MONTH(Table_246[[#This Row],[Data]])) -> 1 | B25: 46037 | C25: Lixa De Unha | D25: 2 | E25: aleatorio | F25: Fisica | G25: =IFERROR(VLOOKUP(C25,PROD!$A$2:$E$1204,5,0),"0") -> 0 | H25: =Table_246[[#This Row],[QT]]*Table_246[[#This Row],[Custo Un]] -> 0 | I25: 0.5 | J25: =I25*D25 -> 1 | K25: =I25*D25 -> 1 | L25: =Table_246[[#This Row],[Valor da venda]]-Table_246[[#This Row],[Valor gasto]] -> 1 | M25: =IFERROR(L25/K25, 0) -> 1 | N25: Transferido | O25: =IF([1]!Table_246[[#This Row],[Coluna2]]>0.5, "🔥 Excelente", IF([1]!Table_246[[#This Row],[Coluna2]]>0.4, "👍 Bom", "⚠️ Baixo")) -> 🔥 Excelente
A26: =IF(Table_246[[#This Row],[Data]]="","",MONTH(Table_246[[#This Row],[Data]])) -> 1 | B26: 46037 | C26: Pelicula 3D | D26: 1 | E26: aleatorio | F26: Fisica | G26: =IFERROR(VLOOKUP(C26,PROD!$A$2:$E$1204,5,0),"0") -> 3 | H26: =Table_246[[#This Row],[QT]]*Table_246[[#This Row],[Custo Un]] -> 3 | I26: 10 | J26: =I26*D26 -> 10 | K26: =I26*D26 -> 10 | L26: =Table_246[[#This Row],[Valor da venda]]-Table_246[[#This Row],[Valor gasto]] -> 7 | M26: =IFERROR(L26/K26, 0) -> 0.7 | N26: Transferido | O26: =IF([1]!Table_246[[#This Row],[Coluna2]]>0.5, "🔥 Excelente", IF([1]!Table_246[[#This Row],[Coluna2]]>0.4, "👍 Bom", "⚠️ Baixo")) -> 🔥 Excelente
A27: =IF(Table_246[[#This Row],[Data]]="","",MONTH(Table_246[[#This Row],[Data]])) -> 1 | B27: 46038 | C27: Chip Sem Recarga | D27: 1 | E27: aleatorio | F27: Fisica | G27: 11 | H27: =Table_246[[#This Row],[QT]]*Table_246[[#This Row],[Custo Un]] -> 11 | I27: 20 | J27: =I27*D27 -> 20 | K27: =I27*D27 -> 20 | L27: =Table_246[[#This Row],[Valor da venda]]-Table_246[[#This Row],[Valor gasto]] -> 9 | M27: =IFERROR(L27/K27, 0) -> 0.45 | N27: Transferido | O27: =IF([1]!Table_246[[#This Row],[Coluna2]]>0.5, "🔥 Excelente", IF([1]!Table_246[[#This Row],[Coluna2]]>0.4, "👍 Bom", "⚠️ Baixo")) -> 👍 Bom
A28: =IF(Table_246[[#This Row],[Data]]="","",MONTH(Table_246[[#This Row],[Data]])) -> 1 | B28: 46038 | C28: Brinquedo Arminha | D28: 1 | E28: daniel | F28: Fisica | G28: 12 | H28: =Table_246[[#This Row],[QT]]*Table_246[[#This Row],[Custo Un]] -> 12 | I28: 25 | J28: =I28*D28 -> 25 | K28: =I28*D28 -> 25 | L28: =Table_246[[#This Row],[Valor da venda]]-Table_246[[#This Row],[Valor gasto]] -> 13 | M28: =IFERROR(L28/K28, 0) -> 0.52 | N28: Transferido | O28: =IF([1]!Table_246[[#This Row],[Coluna2]]>0.5, "🔥 Excelente", IF([1]!Table_246[[#This Row],[Coluna2]]>0.4, "👍 Bom", "⚠️ Baixo")) -> 🔥 Excelente
A29: =IF(Table_246[[#This Row],[Data]]="","",MONTH(Table_246[[#This Row],[Data]])) -> 1 | B29: 46041 | C29: Impressao Preta | D29: 2 | E29: aleatorio | F29: Fisica | G29: =IFERROR(VLOOKUP(C29,PROD!$A$2:$E$1204,5,0),"0") -> 0.07 | H29: =Table_246[[#This Row],[QT]]*Table_246[[#This Row],[Custo Un]] -> 0.14 | I29: 1 | J29: =I29*D29 -> 2 | K29: =I29*D29 -> 2 | L29: =Table_246[[#This Row],[Valor da venda]]-Table_246[[#This Row],[Valor gasto]] -> 1.86 | M29: =IFERROR(L29/K29, 0) -> 0.93 | N29: Transferido | O29: =IF([1]!Table_246[[#This Row],[Coluna2]]>0.5, "🔥 Excelente", IF([1]!Table_246[[#This Row],[Coluna2]]>0.4, "👍 Bom", "⚠️ Baixo")) -> 🔥 Excelente
A30: =IF(Table_246[[#This Row],[Data]]="","",MONTH(Table_246[[#This Row],[Data]])) -> 1 | B30: 46041 | C30: Caixa De Som Pc | D30: 1 | E30: aleatorio | F30: Fisica | G30: 15 | H30: =Table_246[[#This Row],[QT]]*Table_246[[#This Row],[Custo Un]] -> 15 | I30: 25 | J30: =I30*D30 -> 25 | K30: =I30*D30 -> 25 | L30: =Table_246[[#This Row],[Valor da venda]]-Table_246[[#This Row],[Valor gasto]] -> 10 | M30: =IFERROR(L30/K30, 0) -> 0.4 | N30: Transferido | O30: =IF([1]!Table_246[[#This Row],[Coluna2]]>0.5, "🔥 Excelente", IF([1]!Table_246[[#This Row],[Coluna2]]>0.4, "👍 Bom", "⚠️ Baixo")) -> ⚠️ Baixo
A31: =IF(Table_246[[#This Row],[Data]]="","",MONTH(Table_246[[#This Row],[Data]])) -> 1 | B31: 46041 | C31: Bolinha De Gel | D31: 1 | E31: aleatorio | F31: Fisica | G31: 2.5 | H31: =Table_246[[#This Row],[QT]]*Table_246[[#This Row],[Custo Un]] -> 2.5 | I31: 5 | J31: =I31*D31 -> 5 | K31: =I31*D31 -> 5 | L31: =Table_246[[#This Row],[Valor da venda]]-Table_246[[#This Row],[Valor gasto]] -> 2.5 | M31: =IFERROR(L31/K31, 0) -> 0.5 | N31: Transferido | O31: =IF([1]!Table_246[[#This Row],[Coluna2]]>0.5, "🔥 Excelente", IF([1]!Table_246[[#This Row],[Coluna2]]>0.4, "👍 Bom", "⚠️ Baixo")) -> 👍 Bom
A32: =IF(Table_246[[#This Row],[Data]]="","",MONTH(Table_246[[#This Row],[Data]])) -> 1 | B32: 46041 | C32: Serviço Aleatorio | D32: 1 | E32: aleatorio | F32: Fisica | G32: =IFERROR(VLOOKUP(C32,PROD!$A$2:$E$1204,5,0),"0") -> 0 | H32: =Table_246[[#This Row],[QT]]*Table_246[[#This Row],[Custo Un]] -> 0 | I32: 30 | J32: =I32*D32 -> 30 | K32: =I32*D32 -> 30 | L32: =Table_246[[#This Row],[Valor da venda]]-Table_246[[#This Row],[Valor gasto]] -> 30 | M32: =IFERROR(L32/K32, 0) -> 1 | N32: Transferido | O32: =IF([1]!Table_246[[#This Row],[Coluna2]]>0.5, "🔥 Excelente", IF([1]!Table_246[[#This Row],[Coluna2]]>0.4, "👍 Bom", "⚠️ Baixo")) -> 🔥 Excelente
A33: =IF(Table_246[[#This Row],[Data]]="","",MONTH(Table_246[[#This Row],[Data]])) -> 1 | B33: 46039 | C33: Impressao Preta | D33: 8 | E33: aleatorio | F33: Fisica | G33: =IFERROR(VLOOKUP(C33,PROD!$A$2:$E$1204,5,0),"0") -> 0.07 | H33: =Table_246[[#This Row],[QT]]*Table_246[[#This Row],[Custo Un]] -> 0.56 | I33: 1 | J33: =I33*D33 -> 8 | K33: =I33*D33 -> 8 | L33: =Table_246[[#This Row],[Valor da venda]]-Table_246[[#This Row],[Valor gasto]] -> 7.44 | M33: =IFERROR(L33/K33, 0) -> 0.93 | N33: Transferido | O33: =IF([1]!Table_246[[#This Row],[Coluna2]]>0.5, "🔥 Excelente", IF([1]!Table_246[[#This Row],[Coluna2]]>0.4, "👍 Bom", "⚠️ Baixo")) -> 🔥 Excelente
A34: =IF(Table_246[[#This Row],[Data]]="","",MONTH(Table_246[[#This Row],[Data]])) -> 1 | B34: 46041 | C34: Bleybleyd | D34: 1 | E34: aleatorio | F34: Fisica | G34: 25 | H34: =Table_246[[#This Row],[QT]]*Table_246[[#This Row],[Custo Un]] -> 25 | I34: 50 | J34: =I34*D34 -> 50 | K34: =I34*D34 -> 50 | L34: =Table_246[[#This Row],[Valor da venda]]-Table_246[[#This Row],[Valor gasto]] -> 25 | M34: =IFERROR(L34/K34, 0) -> 0.5 | N34: Transferido | O34: =IF([1]!Table_246[[#This Row],[Coluna2]]>0.5, "🔥 Excelente", IF([1]!Table_246[[#This Row],[Coluna2]]>0.4, "👍 Bom", "⚠️ Baixo")) -> 👍 Bom
A35: =IF(Table_246[[#This Row],[Data]]="","",MONTH(Table_246[[#This Row],[Data]])) -> 1 | B35: 46039 | C35: Fone P9 | D35: 1 | E35: brinquedo | F35: Fisica | G35: 20 | H35: =Table_246[[#This Row],[QT]]*Table_246[[#This Row],[Custo Un]] -> 20 | I35: 40 | J35: =I35*D35 -> 40 | K35: =I35*D35 -> 40 | L35: =Table_246[[#This Row],[Valor da venda]]-Table_246[[#This Row],[Valor gasto]] -> 20 | M35: =IFERROR(L35/K35, 0) -> 0.5 | N35: Transferido | O35: =IF([1]!Table_246[[#This Row],[Coluna2]]>0.5, "🔥 Excelente", IF([1]!Table_246[[#This Row],[Coluna2]]>0.4, "👍 Bom", "⚠️ Baixo")) -> 👍 Bom
A36: =IF(Table_246[[#This Row],[Data]]="","",MONTH(Table_246[[#This Row],[Data]])) -> 1 | B36: 46042 | C36: Moeba | D36: 1 | E36: remedio | F36: Fisica | G36: 5 | H36: =Table_246[[#This Row],[QT]]*Table_246[[#This Row],[Custo Un]] -> 5 | I36: 10 | J36: =I36*D36 -> 10 | K36: =I36*D36 -> 10 | L36: =Table_246[[#This Row],[Valor da venda]]-Table_246[[#This Row],[Valor gasto]] -> 5 | M36: =IFERROR(L36/K36, 0) -> 0.5 | N36: Transferido | O36: =IF([1]!Table_246[[#This Row],[Coluna2]]>0.5, "🔥 Excelente", IF([1]!Table_246[[#This Row],[Coluna2]]>0.4, "👍 Bom", "⚠️ Baixo")) -> 👍 Bom
A37: =IF(Table_246[[#This Row],[Data]]="","",MONTH(Table_246[[#This Row],[Data]])) -> 1 | B37: 46042 | C37: Cabo Colorido | D37: 1 | E37: aleatorio | F37: Fisica | G37: 5 | H37: =Table_246[[#This Row],[QT]]*Table_246[[#This Row],[Custo Un]] -> 5 | I37: 10 | J37: =I37*D37 -> 10 | K37: =I37*D37 -> 10 | L37: =Table_246[[#This Row],[Valor da venda]]-Table_246[[#This Row],[Valor gasto]] -> 5 | M37: =IFERROR(L37/K37, 0) -> 0.5 | N37: Transferido | O37: =IF([1]!Table_246[[#This Row],[Coluna2]]>0.5, "🔥 Excelente", IF([1]!Table_246[[#This Row],[Coluna2]]>0.4, "👍 Bom", "⚠️ Baixo")) -> 👍 Bom
A38: =IF(Table_246[[#This Row],[Data]]="","",MONTH(Table_246[[#This Row],[Data]])) -> 1 | B38: 46042 | C38: Cabo Iphone 20W | D38: 1 | E38: ruiva | F38: Fisica | G38: =IFERROR(VLOOKUP(C38,PROD!$A$2:$E$1204,5,0),"0") -> 6 | H38: =Table_246[[#This Row],[QT]]*Table_246[[#This Row],[Custo Un]] -> 6 | I38: 20 | J38: =I38*D38 -> 20 | K38: =I38*D38 -> 20 | L38: =Table_246[[#This Row],[Valor da venda]]-Table_246[[#This Row],[Valor gasto]] -> 14 | M38: =IFERROR(L38/K38, 0) -> 0.7 | N38: Transferido | O38: =IF([1]!Table_246[[#This Row],[Coluna2]]>0.5, "🔥 Excelente", IF([1]!Table_246[[#This Row],[Coluna2]]>0.4, "👍 Bom", "⚠️ Baixo")) -> 🔥 Excelente
A39: =IF(Table_246[[#This Row],[Data]]="","",MONTH(Table_246[[#This Row],[Data]])) -> 1 | B39: 46042 | C39: Capinha Iphone | D39: 1 | E39: ruiva | F39: Fisica | G39: 6.5 | H39: =Table_246[[#This Row],[QT]]*Table_246[[#This Row],[Custo Un]] -> 6.5 | I39: 15 | J39: =I39*D39 -> 15 | K39: =I39*D39 -> 15 | L39: =Table_246[[#This Row],[Valor da venda]]-Table_246[[#This Row],[Valor gasto]] -> 8.5 | M39: =IFERROR(L39/K39, 0) -> 0.56666667 | N39: Transferido | O39: =IF([1]!Table_246[[#This Row],[Coluna2]]>0.5, "🔥 Excelente", IF([1]!Table_246[[#This Row],[Coluna2]]>0.4, "👍 Bom", "⚠️ Baixo")) -> 🔥 Excelente
A40: =IF(Table_246[[#This Row],[Data]]="","",MONTH(Table_246[[#This Row],[Data]])) -> 1 | B40: 46042 | C40: Cabo De Força - 3 Pinos | D40: 1 | E40: aleatorio | F40: Fisica | G40: =IFERROR(VLOOKUP(C40,PROD!$A$2:$E$1204,5,0),"0") -> 6 | H40: =Table_246[[#This Row],[QT]]*Table_246[[#This Row],[Custo Un]] -> 6 | I40: 10 | J40: =I40*D40 -> 10 | K40: =I40*D40 -> 10 | L40: =Table_246[[#This Row],[Valor da venda]]-Table_246[[#This Row],[Valor gasto]] -> 4 | M40: =IFERROR(L40/K40, 0) -> 0.4 | N40: Transferido | O40: =IF([1]!Table_246[[#This Row],[Coluna2]]>0.5, "🔥 Excelente", IF([1]!Table_246[[#This Row],[Coluna2]]>0.4, "👍 Bom", "⚠️ Baixo")) -> ⚠️ Baixo
...

Sheet PROD
A1: Produtos | B1: Compras | C1: Estoque | D1: Vendas | E1: valor | G1: MARCA | H1: MODELO | I1: Q
A2: Adaptador Bluetooth | B2: 1 | C2: =B2-D2 -> 1 | D2: =COUNTIF(Table_246[Produto],Table_1[[#This Row],[Produtos]]) -> 0 | E2: 5 | G2: IPHONE | H2: Iphone 14 PRO MAX | I2: 1
A3: Adaptador Ios P2 | B3: 1 | C3: =B3-D3 -> 1 | D3: =COUNTIF(Table_246[Produto],Table_1[[#This Row],[Produtos]]) -> 0 | E3: 5.9 | G3: IPHONE | H3: Iphone 15 | I3: 1
A4: Adaptador Micro Sd | B4: 1 | C4: =B4-D4 -> 1 | D4: =COUNTIF(Table_246[Produto],Table_1[[#This Row],[Produtos]]) -> 0 | E4: 3.5 | G4: IPHONE | H4: Iphone 15 PRO MAX | I4: 1
A5: Adaptador P2 - P10 | B5: 1 | C5: =B5-D5 -> 1 | D5: =COUNTIF(Table_246[Produto],Table_1[[#This Row],[Produtos]]) -> 0 | E5: 5 | G5: MOTOROLA | H5: G14 | I5: 2
A6: Adaptador P2 Tipo C | B6: 1 | C6: =B6-D6 -> 1 | D6: =COUNTIF(Table_246[Produto],Table_1[[#This Row],[Produtos]]) -> 0 | E6: 8 | G6: MOTOROLA | H6: MOTO edge 30 neo | I6: 2
A7: Adaptador P3X2 - P2 | B7: 1 | C7: =B7-D7 -> 1 | D7: =COUNTIF(Table_246[Produto],Table_1[[#This Row],[Produtos]]) -> 0 | E7: 5 | G7: MOTOROLA | H7: MOTO G30 | I7: 2
A8: Adaptador Rede - Usb | B8: 2 | C8: =B8-D8 -> 2 | D8: =COUNTIF(Table_246[Produto],Table_1[[#This Row],[Produtos]]) -> 0 | G8: SAMSUNG | H8: A10s | I8: 1
A9: Adaptador T | B9: 1 | C9: =B9-D9 -> 1 | D9: =COUNTIF(Table_246[Produto],Table_1[[#This Row],[Produtos]]) -> 0 | E9: 1.5 | G9: SAMSUNG | H9: A22 5g | I9: 3
A10: Adaptador Tipo C Para Usb | B10: 1 | C10: =B10-D10 -> 1 | D10: =COUNTIF(Table_246[Produto],Table_1[[#This Row],[Produtos]]) -> 0 | E10: 3.5 | G10: SAMSUNG | H10: m53 | I10: 1
A11: Adaptador Tomada 2 Entrada | B11: 1 | C11: =B11-D11 -> 1 | D11: =COUNTIF(Table_246[Produto],Table_1[[#This Row],[Produtos]]) -> 0 | E11: 9.9 | G11: XIAOMI | H11: mi 9a | I11: 1
A12: Adaptador V8 - Iphone | B12: 1 | C12: =B12-D12 -> 1 | D12: =COUNTIF(Table_246[Produto],Table_1[[#This Row],[Produtos]]) -> 0 | E12: 3.5 | G12: XIAOMI | H12: Note 10 | I12: 2
A13: Adaptador Vga Para Hdmi | B13: 1 | C13: =B13-D13 -> 1 | D13: =COUNTIF(Table_246[Produto],Table_1[[#This Row],[Produtos]]) -> 0 | E13: 15 | G13: XIAOMI | H13: Note 10 4g | I13: 3
A14: Adaptador Wifi 2.5G | B14: 1 | C14: =B14-D14 -> 1 | D14: =COUNTIF(Table_246[Produto],Table_1[[#This Row],[Produtos]]) -> 0 | E14: 11 | G14: XIAOMI | H14: Note 12s | I14: 1
A15: Adaptador Wifi 2.5G Antena | B15: 1 | C15: =B15-D15 -> 1 | D15: =COUNTIF(Table_246[Produto],Table_1[[#This Row],[Produtos]]) -> 0 | E15: 12 | G15: XIAOMI | H15: pc x3 | I15: 2
A16: Adaptador Wifi 2.5G Antena Ms | B16: 1 | C16: =B16-D16 -> 1 | D16: =COUNTIF(Table_246[Produto],Table_1[[#This Row],[Produtos]]) -> 0 | E16: 9 | G16: XIAOMI | H16: REDMI 12 | I16: 2
A17: Adaptador Wifi 6 | B17: 1 | C17: =B17-D17 -> 1 | D17: =COUNTIF(Table_246[Produto],Table_1[[#This Row],[Produtos]]) -> 0 | E17: 17.18 | G17: XIAOMI | H17: REDMI 12c | I17: 1
A18: Alicate Universal 8 Id-4762A | B18: 1 | C18: =B18-D18 -> 1 | D18: =COUNTIF(Table_246[Produto],Table_1[[#This Row],[Produtos]]) -> 0 | E18: 11 | G18: XIAOMI | H18: REDMI 12 pro 5g | I18: 1
A19: Arma De Hidrogel Ar15 | B19: 1 | C19: =B19-D19 -> 1 | D19: =COUNTIF(Table_246[Produto],Table_1[[#This Row],[Produtos]]) -> 0 | E19: 35 | G19: XIAOMI | H19: REDMI 13c | I19: 2
A20: Arminha De Agua | B20: 99 | C20: =B20-D20 -> 98 | D20: =COUNTIF(Table_246[Produto],Table_1[[#This Row],[Produtos]]) -> 1 | G20: MARCA | H20: MODELO | I20: Q
A21: Balança 10Kg | B21: 1 | C21: =B21-D21 -> 1 | D21: =COUNTIF(Table_246[Produto],Table_1[[#This Row],[Produtos]]) -> 0 | E21: 14 | G21: Privacidade
A22: Balança De Precisão Xm-50522 | B22: 1 | C22: =B22-D22 -> 1 | D22: =COUNTIF(Table_246[Produto],Table_1[[#This Row],[Produtos]]) -> 0 | E22: 16 | G22: IPHONE | H22: 7 / 8 PLUS | I22: 3
A23: Baralho C 2 Jogos Bar-69087 | B23: 1 | C23: =B23-D23 -> 1 | D23: =COUNTIF(Table_246[Produto],Table_1[[#This Row],[Produtos]]) -> 0 | E23: 1 | G23: IPHONE | H23: XR / 11 | I23: 2
A24: Bateria 23A | B24: 1 | C24: =B24-D24 -> 1 | D24: =COUNTIF(Table_246[Produto],Table_1[[#This Row],[Produtos]]) -> 0 | E24: =7.5/5 -> 1.5 | G24: IPHONE | H24: 12 | I24: 1
A25: Bateria 9V | B25: 1 | C25: =B25-D25 -> 1 | D25: =COUNTIF(Table_246[Produto],Table_1[[#This Row],[Produtos]]) -> 0 | E25: 4
A26: Bleybleyd | B26: 99 | C26: =B26-D26 -> 98 | D26: =COUNTIF(Table_246[Produto],Table_1[[#This Row],[Produtos]]) -> 1
A27: Bobbie Goods Caderno | B27: 1 | C27: =B27-D27 -> 1 | D27: =COUNTIF(Table_246[Produto],Table_1[[#This Row],[Produtos]]) -> 0 | E27: 13
A28: Bobbie Goods Card | B28: 1 | C28: =B28-D28 -> 1 | D28: =COUNTIF(Table_246[Produto],Table_1[[#This Row],[Produtos]]) -> 0 | E28: 2.5
A29: Bolinha De Gel | B29: 99 | C29: =B29-D29 -> 98 | D29: =COUNTIF(Table_246[Produto],Table_1[[#This Row],[Produtos]]) -> 1
A30: Boneco Lego | B30: 1 | C30: =B30-D30 -> 1 | D30: =COUNTIF(Table_246[Produto],Table_1[[#This Row],[Produtos]]) -> 0 | E30: 15
A31: Boneco Lego Kit | B31: 99 | C31: =B31-D31 -> 97 | D31: =COUNTIF(Table_246[Produto],Table_1[[#This Row],[Produtos]]) -> 2
A32: Brinquedo Arminha | B32: 99 | C32: =B32-D32 -> 98 | D32: =COUNTIF(Table_246[Produto],Table_1[[#This Row],[Produtos]]) -> 1
A33: Cabeça Carregador 3.1A Ka-5601 | B33: 1 | C33: =B33-D33 -> 1 | D33: =COUNTIF(Table_246[Produto],Table_1[[#This Row],[Produtos]]) -> 0 | E33: 6
A34: Cabo Auxiliar P2 H'Maston | B34: 1 | C34: =B34-D34 -> 1 | D34: =COUNTIF(Table_246[Produto],Table_1[[#This Row],[Produtos]]) -> 0 | E34: 3.5
A35: Cabo Auxiliar P2 Kingo | B35: 1 | C35: =B35-D35 -> 1 | D35: =COUNTIF(Table_246[Produto],Table_1[[#This Row],[Produtos]]) -> 0 | E35: 7
A36: Cabo Auxiliar P2 Le-804 | B36: 1 | C36: =B36-D36 -> 1 | D36: =COUNTIF(Table_246[Produto],Table_1[[#This Row],[Produtos]]) -> 0 | E36: 2.5
A37: Cabo Colorido | B37: 99 | C37: =B37-D37 -> 98 | D37: =COUNTIF(Table_246[Produto],Table_1[[#This Row],[Produtos]]) -> 1
A38: Cabo De Dados Tc Kapbom Kap 1Mtc | B38: 1 | C38: =B38-D38 -> 1 | D38: =COUNTIF(Table_246[Produto],Table_1[[#This Row],[Produtos]]) -> 0 | E38: 3.5
A39: Cabo De Dados V8 Kapbom Kap 1Mv8 | B39: 1 | C39: =B39-D39 -> 1 | D39: =COUNTIF(Table_246[Produto],Table_1[[#This Row],[Produtos]]) -> 0 | E39: 3.5
A40: Cabo De Força - 2 Pinos | B40: 1 | C40: =B40-D40 -> 1 | D40: =COUNTIF(Table_246[Produto],Table_1[[#This Row],[Produtos]]) -> 0
...

Sheet Nota Fiscal
B3: ZM Store | G3: Número | H3: 385 | O3: ZM Store | T3: Número | U3: =H3 -> 385
B5: Endereço | C5: Feicenter box 64 Samambaia N | G5: Data | H5: =TODAY() -> 46216 | O5: Endereço | P5: Feicenter box 64 Samambaia N | T5: Data | U5: =TODAY() -> 46216
B6: Telefone | C6: (61) 98182-0906 | O6: Telefone | P6: (61) 98182-0906
B9: FICHA DE PEDIDO | O9: FICHA DE PEDIDO
B11: Cliente: | O11: Cliente: | P11: =C11 -> 0
B12: Telefone: | C12: 61 9368-7737 | O12: Telefone: | P12: =C12 -> 61 9368-7737
B13: E-mail: | O13: E-mail: | P13: =C13 -> 0
B14: Endereço: | O14: Endereço: | P14: =C14 -> 0
B15: Cidade: | C15: Brasília | E15: CEP: | H15: Vendedor: | I15: Leonardo Coutinho | O15: Cidade: | P15: =C15 -> Brasília | R15: CEP: | S15: =F15 -> 0 | U15: Vendedor: | V15: =I15 -> Leonardo Coutinho
B18: Qtde | C18: Descrição | J18: Valor | K18: Total | O18: Qtde | P18: Descrição | W18: Valor | X18: Total
B19: 1 | C19: Formatação | J19: 70 | K19: =J19*B19 -> 70 | O19: =B19 -> 1 | P19: =C19 -> Formatação | W19: =J19 -> 70 | X19: =K19 -> 70
K20: =J20*B20 -> 0 | O20: =B20 -> 0 | P20: =C20 -> 0 | W20: =J20 -> 0 | X20: =K20 -> 0
K21: =J21*B21 -> 0 | O21: =B21 -> 0 | P21: =C21 -> 0 | W21: =J21 -> 0 | X21: =K21 -> 0
K22: =J22*B22 -> 0 | O22: =B22 -> 0 | P22: =C22 -> 0 | W22: =J22 -> 0 | X22: =K22 -> 0
K23: =J23*B23 -> 0 | O23: =B23 -> 0 | P23: =C23 -> 0 | W23: =J23 -> 0 | X23: =K23 -> 0
K24: =J24*B24 -> 0 | O24: =B24 -> 0 | P24: =C24 -> 0 | W24: =J24 -> 0 | X24: =K24 -> 0
K25: =J25*B25 -> 0 | O25: =B25 -> 0 | P25: =C25 -> 0 | W25: =J25 -> 0 | X25: =K25 -> 0
K26: =J26*B26 -> 0 | O26: =B26 -> 0 | P26: =C26 -> 0 | W26: =J26 -> 0 | X26: =K26 -> 0
K27: =J27*B27 -> 0 | O27: =B27 -> 0 | P27: =C27 -> 0 | W27: =J27 -> 0 | X27: =K27 -> 0
K28: =J28*B28 -> 0 | O28: =B28 -> 0 | P28: =C28 -> 0 | W28: =J28 -> 0 | X28: =K28 -> 0
K29: =J29*B29 -> 0 | O29: =B29 -> 0 | P29: =C29 -> 0 | W29: =J29 -> 0 | X29: =K29 -> 0
K30: =J30*B30 -> 0 | O30: =B30 -> 0 | P30: =C30 -> 0 | W30: =J30 -> 0 | X30: =K30 -> 0
K31: =J31*B31 -> 0 | O31: =B31 -> 0 | P31: =C31 -> 0 | W31: =J31 -> 0 | X31: =K31 -> 0
... K33: =J33*B33 -> 0 | O33: =B33 -> 0 | P33: =C33 -> 0 | W33: =J33 -> 0 | X33: =K33 -> 0
K34: =J34*B34 -> 0 | O34: =B34 -> 0 | P34: =C37 -> 0 | W34: =J34 -> 0 | X34: =K34 -> 0
K35: =J35*B35 -> 0 | O35: =B35 -> 0 | P35: =C35 -> 0 | W35: =J35 -> 0 | X35: =K35 -> 0
K36: =J36*B36 -> 0 | O36: =B36 -> 0 | P36: =C36 -> 0 | W36: =J36 -> 0 | X36: =K36 -> 0
B37: Observação do serviço: | O37: Observação do serviço:
B38: Notebook Samsung RV415, com fonte, formatação simples. | O38: =B38 -> Notebook Samsung RV415, com fonte, formatação simples.
B43: Produtos deixados a mais de 90 dias seram vendidos !! | O43: Produtos deixados a mais de 90 dias seram vendidos !!
B46: Observação | I46: Valor Total | J46: =SUM(K19:K41) -> 70 | O46: Observação | P46: =C46 -> 0 | V46: Valor Total | W46: =SUM(X19:X41) -> 70
I47: Desconto | V47: Desconto | W47: =J47 -> 0
B48: Garantia | C48: 30 dias | E48: Data final | F48: =H5+30 -> 46246 | I48: Valor final | J48: =J46-J47 -> 70 | O48: Garantia | P48: 30 dias | R48: Data final | S48: =U5+30 -> 46246 | V48: Valor final | W48: =W46-W47 -> 70

Sheet Devedores
A1: Vendas CNPJ 2024 | I1: Contas a pagar 03 | N1: Divida | S1: Total dividas | W1: Divida higor | AB1: Produtos | AC1: Compras | AD1: Estoque
A2: Meses | B2: Meses | C2: Vendas Shopee | D2: Presencial | E2: Infinite | F2: Picpay | G2: Magalu | I2: Nome | J2: Nome | K2: dt | N2: Remédio | O2: 10x | P2: 50 | S2: Banco | T2: Valor sem desconto | U2: Valor com desconto | W2: Total divida | X2: =600 -> 600 | AB2: Adaptador IOS p2 | AC2: 1 | AD2: =AC2-AE2 -> 1
A3: 1 | B3: Janeiro | C3: 1528.12 | D3: 120 | E3: 0 | I3: Aluguel | J3: 600 | K3: 10 | N3: Pago | O3: =70+20+50 -> 140 | P3: 500 | S3: Itaú | T3: 537.49 | U3: 227.95 | W3: Falta pagar | X3: =X2-X13 -> 390 | AB3: Adaptador MICRO SD | AC3: 2 | AD3: =AC3-AE3 -> 2
A4: 2 | B4: Fevereiro | C4: 1018.94 | D4: 0 | E4: 0 | I4: NET1 | J4: 100 | K4: 10 | S4: Empresa MP | T4: 394.89 | U4: 177.71 | W4: ------------------- | X4: ------------ | AB4: Adaptador p2 - p10 | AC4: 1 | AD4: =AC4-AE4 -> 1
A5: 3 | B5: Março | C5: 300.48 | D5: 0 | E5: 50 | I5: Mae | J5: 100 | K5: 10 | N5: Total | O5: =O3-500 -> -360 | S5: Cartão MP | T5: 7046.09 | U5: 3107.47 | W5: Produtos pego | AB5: Adaptador p2 tipo c | AC5: 2 | AD5: =AC5-AE5 -> 2
A6: 4 | B6: Abril | C6: 481.53 | D6: 350 | E6: =SUM(2500+30+55+40+65+1805) -> 4495 | I6: CARTAO | J6: 545.16 | K6: 15 | S6: 99 | T6: 11194.34 | U6: 11194.34 | W6: Cadeado com Alarme | X6: 65 | AB6: Adaptador P3X2 - P2 | AC6: 1 | AD6: =AC6-AE6 -> 1
A7: 5 | B7: Maio | C7: 201.6 | D7: 0 | E7: =SUM(60+20+650) -> 730 | I7: RENATA | J7: 10 | K7: 15 | S7: Cartão NU | T7: 27027.55 | U7: 13427.4 | W7: Dinheiro emprestado | X7: 30 | AB7: Adaptador rede - usb | AC7: 1 | AD7: =AC7-AE7 -> 1
A8: 6 | B8: Junho | C8: 291.79 | D8: 0 | E8: =SUM(14+5+50+45+25+2+360+60+44+3+4+3+20+200) -> 835 | I8: CHIP | S8: Empresa NU | T8: =1021.42+14105.35 -> 15126.77 | U8: =532.34+7388.86 -> 7921.2 | W8: Trava de freio a disco | X8: 35 | AB8: Adaptador tipo c para usb | AC8: 7 | AD8: =AC8-AE8 -> 7
A9: 7 | B9: Julho | C9: 444.24 | D9: 0 | E9: =SUM(7+95+2+2500+30+70+30+50+330+15+18+45+10+2+150+10+10+15) -> 3389 | I9: Shopee 1 | J9: 220.8 | K9: 20 | S9: Neon | T9: 3303.72 | U9: 2758.75 | W9: Hub divisor | X9: 80 | AB9: Adaptador Tomada 2 Entradas + 3 Usb Celular Universal Led Variada | AC9: 2 | AD9: =AC9-AE9 -> 2
A10: 8 | B10: Agosto | C10: 552.75 | D10: 0 | E10: =SUM(2+10+6+22.5+3+2+5+2+11) -> 63.5 | I10: Shopee 2 | J10: 220.8 | K10: 20 | S10: Nu PJ | T10: 2434.54 | U10: 1544.43 | AB10: Adaptador v8 - Iphone | AC10: 2 | AD10: =AC10-AE10 -> 2
A11: 9 | B11: Setembro | C11: 234.8 | D11: 0 | E11: =SUM(50+2+42+30+10+5) -> 139 | I11: DARF | J11: 81 | K11: 20 | AB11: Adaptador VGA para HDMI | AC11: 3 | AD11: =AC11-AE11 -> 3
A12: 10 | B12: Outubro | C12: 312.44 | D12: 0 | E12: =SUM(30+10) -> 40 | I12: Aliexpress | J12: 54.47 | K12: 20 | S12: Total | T12: =SUM(T3:T11) -> 67065.39 | U12: =SUM(U3:U11) -> 40359.25 | AB12: Adaptador Wifi 2.5G | AC12: 3 | AD12: =AC12-AE12 -> 3
A13: 11 | B13: Novembro | C13: 564.38 | D13: 0 | G13: 669.7 | I13: NET CPF | J13: 100 | K13: 21 | W13: Total pego | X13: =SUM(X6:X12) -> 210 | AB13: Adaptador Wifi 2.5G Antena | AC13: 1 | AD13: =AC13-AE13 -> 1
A14: 12 | B14: Dezembro | C14: 3223.22 | I14: NET PJ | J14: 100 | K14: 21 | AB14: Adaptador Wifi 2.5G Antena MS | AC14: 1 | AD14: =AC14-AE14 -> 1
A15: Soma | C15: =SUM(C3:C14) -> 9154.29 | D15: =SUM(D3:D14) -> 470 | E15: 9759.5 | F15: =SUM(F3:F14) -> 0 | G15: =SUM(G3:G14) -> 669.7 | I15: AGUA | J15: 100 | K15: 27 | AB15: Alicate Universal 8 Id-4762A | AC15: 1 | AD15: =AC15-AE15 -> 1
A16: Total | C16: =SUM(C15:G15) -> 20053.49 | D16: Falta | E16: =81000-C16 -> 60946.51 | AB16: Amolador de faca | AC16: 2 | AD16: =AC16-AE16 -> 2
I17: TOTAL | J17: =SUM(J3:J15) -> 2232.23 | AB17: Antena Digital | AC17: 0 | AD17: =AC17-AE17 -> 0
A18: Vendas CNPJ 2024 | AB18: Balança 10kg | AC18: 2 | AD18: =AC18-AE18 -> 2
A19: Meses | B19: Meses | C19: Vendas Shopee | D19: Presencial | E19: Infiniti | AB19: Balança de mala | AC19: 1 | AD19: =AC19-AE19 -> 1
A20: 1 | B20: Janeiro | AB20: Balança De Precisão Xm-50522 | AC20: 3 | AD20: =AC20-AE20 -> 3
A21: 2 | B21: Fevereiro | AB21: Baralho C 2 Jogos Bar-69087 | AC21: 1 | AD21: =AC21-AE21 -> 1
A22: 3 | B22: Março | AB22: Baralho C 2 Jogos Bar-69087 | AC22: 5 | AD22: =AC22-AE22 -> 5
A23: 4 | B23: Abril | AB23: Bateria 9v | AC23: 1 | AD23: =AC23-AE23 -> 1
A24: 5 | B24: Maio | AB24: Blindagem | AC24: 1 | AD24: =AC24-AE24 -> 1
A25: 6 | B25: Junho | AB25: Bolsa Multifuncional Masculina De Peito | AC25: 2 | AD25: =AC25-AE25 -> 2
A26: 7 | B26: Julho | AB26: Bolsa Necessaire Organizadora Para Cosméticos | AC26: 1 | AD26: =AC26-AE26 -> 1
A27: 8 | B27: Agosto | AB27: Bomba D'Agua Automatica | AC27: 0 | AD27: =AC27-AE27 -> 0
A28: 9 | B28: Setembro | AB28: Bomba D'Agua manual | AC28: 1 | AD28: =AC28-AE28 -> 1
A29: 10 | B29: Outubro | AB29: Cabo Auxiliar P2 Kingo | AC29: 3 | AD29: =AC29-AE29 -> 3
A30: 11 | B30: Novembro | AB30: Cabo Colorido 2 Metros Iphone | AC30: 1 | AD30: =AC30-AE30 -> 1
A31: 12 | B31: Dezembro | AB31: Cabo Colorido 2 Metros Tipo C | AC31: 5 | AD31: =AC31-AE31 -> 5
A32: Soma | C32: =SUM(C20:C31) -> 0 | D32: =SUM(D20:D31) -> 0 | E32: =SUM(E20:E31) -> 0 | F32: =SUM(F20:F31) -> 0 | G32: =SUM(G20:G31) -> 0 | AB32: Cabo Colorido 2 Metros V8 | AC32: 1 | AD32: =AC32-AE32 -> 1
A33: Total | C33: =SUM(C32:G32) -> 0 | D33: Falta | E33: =81000-C33 -> 81000 | AB33: Cabo Colorido Iphone 1M | AC33: 7 | AD33: =AC33-AE33 -> 7
AB34: Cabo Colorido Tipo C 1M | AC34: 3 | AD34: =AC34-AE34 -> 3
AB35: Cabo Colorido v8 1M | AC35: 1 | AD35: =AC35-AE35 -> 1
AB36: cabo de força | AC36: 1 | AD36: =AC36-AE36 -> 1
AB37: Cabo De Força - Pc | AC37: 1 | AD37: =AC37-AE37 -> 1
AB38: Cabo Hdmi 2M | AC38: 2 | AD38: =AC38-AE38 -> 2
AB39: Cabo HDMI 4 em 1 | AC39: 1 | AD39: =AC39-AE39 -> 1
AB40: Cabo Hdmi 4M | AC40: 1 | AD40: =AC40-AE40 -> 1
...

Sheet jogos
A1: Jogos PS2 | B1: Atual | C1: qt | D1: Vendio | F1: Jogos Xbox | G1: Atual | H1: qt | J1: Peliculas Vendidas | P1: Peliculas Disponiveis
A2: 007 From Russi | B2: =C2-D2 -> 0 | C2: 1 | D2: 1 | F2: 007 Legends | G2: 1 | H2: 1 | J2: QT | K2: marca | L2: Modelo | M2: Compativel | O2: marca | P2: QT | Q2: Modelo | R2: Compativel
A3: Ace Bombat The Belkan War | B3: =C3-D3 -> 2 | C3: 3 | D3: 1 | F3: Ace combat assault horizon | G3: 1 | H3: 1 | J3: 2 | K3: Iphone | L3: XS MAX/ 11 PRO MAX | O3: Iphone | P3: 1 | Q3: 6G
A4: Astro Boy | B4: =C4-D4 -> 4 | C4: 4 | F4: Anarchy Reigns | G4: 1 | H4: 1 | J4: 2 | K4: Iphone | L4: XR / 11 | O4: Iphone | P4: 5 | Q4: 7 / 8 g
A5: Bad Boys miami takedown | B5: =C5-D5 -> 2 | C5: 2 | F5: Arcade | G5: 1 | H5: 1 | J5: 1 | K5: Iphone | L5: 13 | O5: Iphone PRIVACIDADE | P5: 1 | Q5: 7 / 8 g
A6: Barn Yard | B6: =C6-D6 -> 2 | C6: 2 | F6: Army Of Tiio | G6: 1 | H6: 1 | J6: 1 | K6: Iphone | L6: 7G / 8G | O6: Iphone | P6: 1 | Q6: 7 PLUS / 8 PLUS
A7: Batmam begins | B7: =C7-D7 -> 1 | C7: 1 | F7: Batman 3 lego | G7: 2 | H7: 2 | J7: 1 | K7: Iphone | L7: 15 | O7: Iphone PRIVACIDADE | P7: 4 | Q7: 7 PLUS / 8 PLUS
A8: Battlefield 2 Modern Combat | B8: =C8-D8 -> 1 | C8: 1 | F8: Batman Arkham City | G8: 1 | H8: 2 | J8: 1 | K8: Iphone | L8: 12 | O8: Iphone | P8: 3 | Q8: X / XS / 11 PRO | R8: XS - 11 PRO - A01 CORE
A9: Beach Volleyball | B9: =C9-D9 -> 2 | C9: 2 | F9: Bayoneta | G9: 1 | H9: 1 | J9: 1 | K9: Samsung | L9: A13 | O9: Iphone PRIVACIDADE | P9: 1 | Q9: XS / 11
A10: Bem 10 Utimate Alien | B10: =C10-D10 -> 3 | C10: 3 | F10: Bioshock | G10: 1 | H10: 1 | J10: 1 | K10: Samsung | L10: 13 4G | O10: Iphone | P10: 1 | Q10: XS / 11
A11: Bem 10 vilgah attacks | B11: =C11-D11 -> 1 | C11: 1 | F11: Bioshock 2 | G11: 1 | H11: 1 | J11: 1 | K11: Samsung | L11: A15 | O11: Iphone | P11: 2 | Q11: XS MAX | R11: POCO F1 / IPHONE XS MAX / IPHONE 11 PRO MAX
A12: Biohazard Outbreak File 2 | B12: =C12-D12 -> 2 | C12: 2 | F12: Bioshock Infinite | G12: 1 | H12: 1 | J12: 1 | K12: Samsung | L12: A20S | O12: Iphone | P12: 1 | Q12: 12 | R12: 12 PRO / IPHONE 11
A13: Black | B13: =C13-D13 -> 1 | C13: 7 | D13: 6 | F13: Borderlands 2 | G13: 2 | H13: 2 | J13: 1 | K13: Samsung | L13: A30S | O13: Iphone | P13: 1 | Q13: 12 PRO
A14: Blade 2 | B14: =C14-D14 -> 1 | C14: 1 | F14: Bound By Flame | G14: 1 | H14: 1 | J14: 1 | K14: Samsung | L14: A32 4G | O14: Iphone | P14: 2 | Q14: 12 PRO MAX
A15: Bomba Patch | B15: =C15-D15 -> 2 | C15: 2 | F15: BRAZUKAS 2023 | G15: 1 | H15: 1 | J15: 1 | K15: Samsung | L15: A24 | O15: Iphone | P15: 2 | Q15: 13 / 13 PRO | R15: IPHONE 13 / IPHONE 14 / E 14 PRO
A16: Bomba Patch 2024 | B16: =C16-D16 -> 0 | C16: 0 | F16: BRAZUKAS 2025 | G16: 1 | J16: 1 | K16: Samsung | L16: A51 | O16: Iphone | P16: 6 | Q16: 13 PRO MAX
A17: Bomba Patch Leonardo | B17: =C17-D17 -> 3 | C17: 3 | F17: Bulletstorm | G17: 1 | J17: 1 | K17: Samsung | L17: A53 | O17: Iphone PRIVACIDADE | P17: 2 | Q17: 13 PRO MAX / 14 PLUS
A18: Bomba Patch Mix Itaqui 2024 | B18: =C18-D18 -> 2 | C18: 2 | F18: Cabelas Dangerous Hunter 20 | G18: 1 | H18: 1 | J18: 1 | K18: Samsung | L18: A50 | O18: Iphone | P18: 1 | Q18: 14 / 14 PRO | R18: IPHONE 13 PRO / IPHONE 14 / IPHONE 13
A19: Bomberman Kart 3 | B19: =C19-D19 -> 1 | C19: 1 | F19: Cabelas Survival | G19: 1 | H19: 1 | J19: 1 | K19: Samsung | L19: A70 | O19: Iphone PRIVACIDADE | P19: 1 | Q19: 14 / 14 PRO | R19: IPHONE 13 PRO / IPHONE 14 / IPHONE 13
A20: Bomberman Land 3 | B20: =C20-D20 -> 2 | C20: 2 | F20: Calela African | G20: 1 | H20: 1 | J20: 1 | K20: Samsung | L20: S24 FE | O20: Iphone PRIVACIDADE | P20: 1 | Q20: 14 PRO MAX | R20: IPHONE 14 PRO MAX - IPHONE 13 PRO MAX - IPHONE 15 PRO MAX
A21: Bully | B21: =C21-D21 -> 0 | C21: 4 | D21: 4 | F21: call of duty black ops | G21: 1 | H21: 1 | J21: 1 | K21: Motorola | L21: G30 | O21: Iphone | P21: 3 | Q21: 14 PRO MAX | R21: IPHONE 14 PRO MAX - IPHONE 13 PRO MAX - IPHONE 15 PRO MAX
A22: Burnout 3 | B22: =C22-D22 -> 1 | C22: 5 | D22: 4 | F22: Capcom Digital Collection | G22: 1 | J22: 1 | K22: Motorola | L22: G73 | O22: Iphone | P22: 5 | Q22: 15 | R22: IPHONE 15 - IPHONE 15 PRO
